input,returncode,message
/data/SoftwareTools/WAD_Software/WADplugins/WAD_Python/Tools/PluginTesting/TestingOutput/2015-07-03/Plugin_development/CT/CT_Catphan_500/series/config_catphan503_asz.000/input.xml,1,"Traceback (most recent call last):   File /data/SoftwareTools/WAD_Software/WADplugins/WAD_Python/pywadplugin.py, line 9, in <module>     pluginWrapper(sys.argv[1])   File /data/SoftwareTools/WAD_Software/WADplugins/WAD_Python/pyWAD/base.py, line 52, in pluginWrapper     function(plugin_data, plugin_results, params=action['params'])   File /data/SoftwareTools/WAD_Software/WADplugins/WAD_Python/Plugin_development/CT/CT_Catphan_500/Analyzer.py, line 529, in catphan500     catphan._load_files(filelist)   File /data/SoftwareTools/WAD_Software/WADplugins/WAD_Python/Plugin_development/CT/CT_Catphan_500/Analyzer.py, line 121, in _load_files     self._sort_images(images, im_order)   File /data/SoftwareTools/WAD_Software/WADplugins/WAD_Python/Plugin_development/CT/CT_Catphan_500/Analyzer.py, line 144, in _sort_images     self.images[item,:,:] = image_list[idx] IndexError: index 45 is out of bounds for axis 0 with size 45 "

ERROR,type
